Workbook

Sheet Dashboard
A2: BharatVote — Election Results & Analytics Dashboard
A3: Comprehensive Election Analytics • Real-Time Insights • Data-Driven Democracy
A6: Total Registered Voters | D6: Total Votes Cast | G6: Overall Turnout % | J6: Leading Party
A7: =COUNTA('Raw Data'!B2:B1001) -> 1000 | D7: =COUNTIF('Raw Data'!E2:E1001,TRUE()) -> 491 | G7: =COUNTIF('Raw Data'!E2:E1001,TRUE())/COUNTA('Raw Data'!B2:B1001) -> 0.491 | J7: =INDEX(Helper!F3:F5,MATCH(MAX(Helper!G3:G5),Helper!G3:G5,0)) -> Unity Alliance
A10: DETAILED ANALYTICS
A12: CONSTITUENCY PERFORMANCE
A13: Constituency | C13: Registered | E13: Votes Cast | F13: Turnout %
A14: =Helper!A3 -> New Delhi | C14: =Helper!B3 -> 321 | E14: =Helper!C3 -> 164 | F14: =Helper!D3 -> 0.51090343
A15: =Helper!A4 -> Mumbai South | C15: =Helper!B4 -> 335 | E15: =Helper!C4 -> 157 | F15: =Helper!D4 -> 0.46865672
A16: =Helper!A5 -> Bangalore Central | C16: =Helper!B5 -> 344 | E16: =Helper!C5 -> 170 | F16: =Helper!D5 -> 0.49418605
A19: VOTER APPROVAL STATUS
A20: Status | C20: Count | E20: Share %
A21: =Helper!A25 -> Approved | C21: =Helper!B25 -> 303 | E21: =Helper!C25 -> 0.303
A22: =Helper!A26 -> Pending | C22: =Helper!B26 -> 369 | E22: =Helper!C26 -> 0.369
A23: =Helper!A27 -> Rejected | C23: =Helper!B27 -> 328 | E23: =Helper!C27 -> 0.328
A46: KEY INSIGHTS
A47: ="Highest turnout: "&INDEX(Helper!A3:A5,MATCH(MAX(Helper!D3:D5),Helper!D3:D5,0))&" at "&TEXT(MAX(Helper!D3:D5),"0.0%")&", lowest: "&INDEX(Helper!A3:A5,MATCH(MIN(Helper!D3:D5),Helper!D3:D5,0))&" at "&TEXT(MIN(Helper!D3:D5),"0.0%")&"." -> Highest turnout: New Delhi at 51.1%, lowest: Mumbai South at 46.9%.
A48: ="Leading party: "&INDEX(Helper!F3:F5,MATCH(MAX(Helper!G3:G5),Helper!G3:G5,0))&" with "&TEXT(MAX(Helper!H3:H5),"0.0%")&" vote share." -> Leading party: Unity Alliance with 33.6% vote share.
A49: ="Voter approval pipeline: "&TEXT(Helper!C25,"0.0%")&" approved, "&TEXT(Helper!C26,"0.0%")&" pending, "&TEXT(Helper!C27,"0.0%")&" rejected." -> Voter approval pipeline: 30.3% approved, 36.9% pending, 32.8% rejected.
A51: ="Report generated: "&TEXT(TODAY(),"dd mmm yyyy") -> Report generated: 18 Jul 2026 | H51: Data source: BharatVote Voter & Election Database
A53: BharatVote © 2026 • Powered by EPIC-Based Voter Registration • Constituency-Locked Voting System

Sheet Raw Data
A1: ID | B1: Voter EPIC Number | C1: Voter Name | D1: Voter Constituency | E1: Has Voted | F1: Voter Status | G1: Candidate ID | H1: Candidate Name | I1: Candidate Party | J1: Candidate Constituency | K1: Candidate Votes | L1: Vote Timestamp
A2: 1 | B2: EPIC100001 | C2: Annabel Pactat | D2: New Delhi | E2: =TRUE() -> TRUE | F2: REJECTED | G2: 1 | H2: Shurwood Berr | I2: Progressive Party | J2: Mumbai South | K2: =IF(E2=TRUE(),1,0) -> 1 | L2: 46218.292
A3: 2 | B3: EPIC100002 | C3: Bernhard Ellings | D3: New Delhi | E3: =FALSE() -> FALSE | F3: APPROVED | G3: 2 | H3: Gregory Urrey | I3: Progressive Party | J3: Mumbai South | K3: =IF(E3=TRUE(),1,0) -> 0
A4: 3 | B4: EPIC100003 | C4: Andres Schankel | D4: Mumbai South | E4: =TRUE() -> TRUE | F4: PENDING | G4: 3 | H4: Ole Columbine | I4: Unity Alliance | J4: Bangalore Central | K4: =IF(E4=TRUE(),1,0) -> 1 | L4: 46218.292
A5: 4 | B5: EPIC100004 | C5: Carrissa Feeney | D5: Bangalore Central | E5: =TRUE() -> TRUE | F5: PENDING | G5: 4 | H5: Noella Jorgensen | I5: Progressive Party | J5: Bangalore Central | K5: =IF(E5=TRUE(),1,0) -> 1 | L5: 46218.293
A6: 5 | B6: EPIC100005 | C6: Bette Sayse | D6: Bangalore Central | E6: =TRUE() -> TRUE | F6: APPROVED | G6: 5 | H6: Lorri Forseith | I6: Progressive Party | J6: Mumbai South | K6: =IF(E6=TRUE(),1,0) -> 1 | L6: 46218.293
A7: 6 | B7: EPIC100006 | C7: Berty Georgescu | D7: Bangalore Central | E7: =TRUE() -> TRUE | F7: PENDING | G7: 6 | H7: Malissia Loudiane | I7: People's Front | J7: Bangalore Central | K7: =IF(E7=TRUE(),1,0) -> 1 | L7: 46218.294
A8: 7 | B8: EPIC100007 | C8: Dorena Sagerson | D8: Bangalore Central | E8: =FALSE() -> FALSE | F8: REJECTED | G8: 7 | H8: Care Ciabatteri | I8: Progressive Party | J8: Bangalore Central | K8: =IF(E8=TRUE(),1,0) -> 0
A9: 8 | B9: EPIC100008 | C9: Laurent Prine | D9: New Delhi | E9: =FALSE() -> FALSE | F9: REJECTED | G9: 8 | H9: Phineas Shelsher | I9: People's Front | J9: New Delhi | K9: =IF(E9=TRUE(),1,0) -> 0
A10: 9 | B10: EPIC100009 | C10: Vilhelmina State | D10: Mumbai South | E10: =TRUE() -> TRUE | F10: PENDING | G10: 9 | H10: Halette Creggan | I10: Progressive Party | J10: Mumbai South | K10: =IF(E10=TRUE(),1,0) -> 1 | L10: 46218.294
A11: 10 | B11: EPIC100010 | C11: Maxi Filmer | D11: Bangalore Central | E11: =FALSE() -> FALSE | F11: PENDING | G11: 10 | H11: Merell Crass | I11: Unity Alliance | J11: Mumbai South | K11: =IF(E11=TRUE(),1,0) -> 0
A12: 11 | B12: EPIC100011 | C12: Ernest Marsden | D12: New Delhi | E12: =TRUE() -> TRUE | F12: APPROVED | G12: 11 | H12: Tarra Pulhoster | I12: People's Front | J12: Bangalore Central | K12: =IF(E12=TRUE(),1,0) -> 1 | L12: 46218.297
A13: 12 | B13: EPIC100012 | C13: Kendrick Hasslocher | D13: Mumbai South | E13: =TRUE() -> TRUE | F13: REJECTED | G13: 12 | H13: Grantley Medcraft | I13: Progressive Party | J13: New Delhi | K13: =IF(E13=TRUE(),1,0) -> 1 | L13: 46218.297
A14: 13 | B14: EPIC100013 | C14: Morlee O'Neill | D14: New Delhi | E14: =TRUE() -> TRUE | F14: PENDING | G14: 13 | H14: Rolfe Lorraway | I14: Unity Alliance | J14: Mumbai South | K14: =IF(E14=TRUE(),1,0) -> 1 | L14: 46218.298
A15: 14 | B15: EPIC100014 | C15: Bella Bullocke | D15: New Delhi | E15: =FALSE() -> FALSE | F15: PENDING | G15: 14 | H15: Jennie Mabbutt | I15: Unity Alliance | J15: Mumbai South | K15: =IF(E15=TRUE(),1,0) -> 0
A16: 15 | B16: EPIC100015 | C16: Konstantine Terese | D16: Mumbai South | E16: =TRUE() -> TRUE | F16: APPROVED | G16: 15 | H16: Maximo Scouller | I16: People's Front | J16: Mumbai South | K16: =IF(E16=TRUE(),1,0) -> 1 | L16: 46218.299
A17: 16 | B17: EPIC100016 | C17: Carlene Beviss | D17: Mumbai South | E17: =FALSE() -> FALSE | F17: REJECTED | G17: 16 | H17: Allard Morais | I17: Unity Alliance | J17: Mumbai South | K17: =IF(E17=TRUE(),1,0) -> 0
A18: 17 | B18: EPIC100017 | C18: Lacy Staves | D18: New Delhi | E18: =FALSE() -> FALSE | F18: APPROVED | G18: 17 | H18: Colleen Jeffrey | I18: People's Front | J18: Bangalore Central | K18: =IF(E18=TRUE(),1,0) -> 0
A19: 18 | B19: EPIC100018 | C19: Imogene Grigoryov | D19: New Delhi | E19: =TRUE() -> TRUE | F19: APPROVED | G19: 18 | H19: Michele Paradise | I19: Unity Alliance | J19: Bangalore Central | K19: =IF(E19=TRUE(),1,0) -> 1 | L19: 46218.299
A20: 19 | B20: EPIC100019 | C20: Whit Deplacido | D20: New Delhi | E20: =TRUE() -> TRUE | F20: REJECTED | G20: 19 | H20: Galvin Barhims | I20: People's Front | J20: Bangalore Central | K20: =IF(E20=TRUE(),1,0) -> 1 | L20: 46218.3
A21: 20 | B21: EPIC100020 | C21: Trumann Slidders | D21: Bangalore Central | E21: =TRUE() -> TRUE | F21: PENDING | G21: 20 | H21: Peria Loggie | I21: People's Front | J21: Mumbai South | K21: =IF(E21=TRUE(),1,0) -> 1 | L21: 46218.303
A22: 21 | B22: EPIC100021 | C22: Ken Rowswell | D22: Bangalore Central | E22: =FALSE() -> FALSE | F22: APPROVED | G22: 21 | H22: Blane Cammis | I22: Unity Alliance | J22: New Delhi | K22: =IF(E22=TRUE(),1,0) -> 0
A23: 22 | B23: EPIC100022 | C23: Alano Eyers | D23: Bangalore Central | E23: =TRUE() -> TRUE | F23: APPROVED | G23: 22 | H23: Trey Oliphard | I23: Progressive Party | J23: Mumbai South | K23: =IF(E23=TRUE(),1,0) -> 1 | L23: 46218.306
A24: 23 | B24: EPIC100023 | C24: Ferrell Whatman | D24: New Delhi | E24: =TRUE() -> TRUE | F24: APPROVED | G24: 23 | H24: Raye Filov | I24: Unity Alliance | J24: New Delhi | K24: =IF(E24=TRUE(),1,0) -> 1 | L24: 46218.308
A25: 24 | B25: EPIC100024 | C25: Nikita Sadd | D25: Mumbai South | E25: =TRUE() -> TRUE | F25: PENDING | G25: 24 | H25: Marc Dhillon | I25: Unity Alliance | J25: New Delhi | K25: =IF(E25=TRUE(),1,0) -> 1 | L25: 46218.31
A26: 25 | B26: EPIC100025 | C26: Maximilien Mazella | D26: Mumbai South | E26: =TRUE() -> TRUE | F26: PENDING | G26: 25 | H26: Normie Grafom | I26: Progressive Party | J26: Mumbai South | K26: =IF(E26=TRUE(),1,0) -> 1 | L26: 46218.31
A27: 26 | B27: EPIC100026 | C27: Horacio Lawley | D27: New Delhi | E27: =TRUE() -> TRUE | F27: PENDING | G27: 26 | H27: Darice Keatley | I27: Progressive Party | J27: Mumbai South | K27: =IF(E27=TRUE(),1,0) -> 1 | L27: 46218.311
A28: 27 | B28: EPIC100027 | C28: Teressa Camilleri | D28: Mumbai South | E28: =TRUE() -> TRUE | F28: PENDING | G28: 27 | H28: Grover Flynn | I28: Progressive Party | J28: New Delhi | K28: =IF(E28=TRUE(),1,0) -> 1 | L28: 46218.312
A29: 28 | B29: EPIC100028 | C29: Quintana Balsellie | D29: Mumbai South | E29: =FALSE() -> FALSE | F29: APPROVED | G29: 28 | H29: Morlee Houlaghan | I29: Progressive Party | J29: Mumbai South | K29: =IF(E29=TRUE(),1,0) -> 0
A30: 29 | B30: EPIC100029 | C30: Maxwell Fernan | D30: New Delhi | E30: =FALSE() -> FALSE | F30: PENDING | G30: 29 | H30: Alfie Spurret | I30: Unity Alliance | J30: Bangalore Central | K30: =IF(E30=TRUE(),1,0) -> 0
A31: 30 | B31: EPIC100030 | C31: Hedda Merring | D31: Mumbai South | E31: =TRUE() -> TRUE | F31: PENDING | G31: 30 | H31: Erny Openshaw | I31: Progressive Party | J31: Mumbai South | K31: =IF(E31=TRUE(),1,0) -> 1 | L31: 46218.313
A32: 31 | B32: EPIC100031 | C32: Massimiliano Raft | D32: Mumbai South | E32: =TRUE() -> TRUE | F32: PENDING | G32: 31 | H32: Myra Willacot | I32: Progressive Party | J32: Bangalore Central | K32: =IF(E32=TRUE(),1,0) -> 1 | L32: 46218.314
A33: 32 | B33: EPIC100032 | C33: Tyrus Kunrad | D33: New Delhi | E33: =TRUE() -> TRUE | F33: REJECTED | G33: 32 | H33: Lindy Medcraft | I33: Progressive Party | J33: New Delhi | K33: =IF(E33=TRUE(),1,0) -> 1 | L33: 46218.315
A34: 33 | B34: EPIC100033 | C34: Isadora Philip | D34: Bangalore Central | E34: =FALSE() -> FALSE | F34: APPROVED | G34: 33 | H34: Vina Caffrey | I34: Unity Alliance | J34: Mumbai South | K34: =IF(E34=TRUE(),1,0) -> 0
A35: 34 | B35: EPIC100034 | C35: Dud Schulze | D35: New Delhi | E35: =FALSE() -> FALSE | F35: PENDING | G35: 34 | H35: Kristien Caillou | I35: People's Front | J35: New Delhi | K35: =IF(E35=TRUE(),1,0) -> 0
A36: 35 | B36: EPIC100035 | C36: Batsheva Cuttle | D36: New Delhi | E36: =FALSE() -> FALSE | F36: REJECTED | G36: 35 | H36: Pansie Ormerod | I36: Progressive Party | J36: New Delhi | K36: =IF(E36=TRUE(),1,0) -> 0
A37: 36 | B37: EPIC100036 | C37: Thaddeus Lipman | D37: Bangalore Central | E37: =FALSE() -> FALSE | F37: REJECTED | G37: 36 | H37: Melisse Pantecost | I37: Unity Alliance | J37: Bangalore Central | K37: =IF(E37=TRUE(),1,0) -> 0
A38: 37 | B38: EPIC100037 | C38: Lindie Ruit | D38: Mumbai South | E38: =FALSE() -> FALSE | F38: APPROVED | G38: 37 | H38: Abigail Summerside | I38: People's Front | J38: Bangalore Central | K38: =IF(E38=TRUE(),1,0) -> 0
A39: 38 | B39: EPIC100038 | C39: Frasco Tassell | D39: Bangalore Central | E39: =FALSE() -> FALSE | F39: APPROVED | G39: 38 | H39: Jessey Domanski | I39: Progressive Party | J39: New Delhi | K39: =IF(E39=TRUE(),1,0) -> 0
A40: 39 | B40: EPIC100039 | C40: Corie MacMurray | D40: Bangalore Central | E40: =FALSE() -> FALSE | F40: APPROVED | G40: 39 | H40: Aida Newark | I40: Progressive Party | J40: Bangalore Central | K40: =IF(E40=TRUE(),1,0) -> 0
...

Sheet Helper
A1: CONSTITUENCY SUMMARY | F1: PARTY VOTE SHARE
A2: Constituency | B2: Registered Voters | C2: Votes Cast | D2: Turnout % | F2: Party | G2: Total Votes | H2: Vote Share %
A3: New Delhi | B3: =COUNTIF('Raw Data'!D2:D1001,A3) -> 321 | C3: =COUNTIFS('Raw Data'!D2:D1001,A3,'Raw Data'!E2:E1001,TRUE()) -> 164 | D3: =IF(B3=0,0,C3/B3) -> 0.51090343 | F3: Progressive Party | G3: =SUMIF('Raw Data'!I2:I1001,F3,'Raw Data'!K2:K1001) -> 161 | H3: =IF(SUM(G$3:G$5)=0,0,G3/SUM(G$3:G$5)) -> 0.32790224
A4: Mumbai South | B4: =COUNTIF('Raw Data'!D2:D1001,A4) -> 335 | C4: =COUNTIFS('Raw Data'!D2:D1001,A4,'Raw Data'!E2:E1001,TRUE()) -> 157 | D4: =IF(B4=0,0,C4/B4) -> 0.46865672 | F4: Unity Alliance | G4: =SUMIF('Raw Data'!I2:I1001,F4,'Raw Data'!K2:K1001) -> 165 | H4: =IF(SUM(G$3:G$5)=0,0,G4/SUM(G$3:G$5)) -> 0.33604888
A5: Bangalore Central | B5: =COUNTIF('Raw Data'!D2:D1001,A5) -> 344 | C5: =COUNTIFS('Raw Data'!D2:D1001,A5,'Raw Data'!E2:E1001,TRUE()) -> 170 | D5: =IF(B5=0,0,C5/B5) -> 0.49418605 | F5: People's Front | G5: =SUMIF('Raw Data'!I2:I1001,F5,'Raw Data'!K2:K1001) -> 165 | H5: =IF(SUM(G$3:G$5)=0,0,G5/SUM(G$3:G$5)) -> 0.33604888
A8: HOURLY CUMULATIVE TURNOUT
A9: Hour | B9: Votes This Hour | C9: Cumulative Votes
A10: 7:00 | B10: =COUNTIFS('Raw Data'!E2:E1001,TRUE(),'Raw Data'!L2:L1001,">="&DATE(2026,7,15)+TIME(7,0,0),'Raw Data'!L2:L1001,"<"&DATE(2026,7,15)+TIME(8,0,0)) -> 39 | C10: =B10 -> 39
A11: 8:00 | B11: =COUNTIFS('Raw Data'!E2:E1001,TRUE(),'Raw Data'!L2:L1001,">="&DATE(2026,7,15)+TIME(8,0,0),'Raw Data'!L2:L1001,"<"&DATE(2026,7,15)+TIME(9,0,0)) -> 57 | C11: =C10+B11 -> 96
A12: 9:00 | B12: =COUNTIFS('Raw Data'!E2:E1001,TRUE(),'Raw Data'!L2:L1001,">="&DATE(2026,7,15)+TIME(9,0,0),'Raw Data'!L2:L1001,"<"&DATE(2026,7,15)+TIME(10,0,0)) -> 46 | C12: =C11+B12 -> 142
A13: 10:00 | B13: =COUNTIFS('Raw Data'!E2:E1001,TRUE(),'Raw Data'!L2:L1001,">="&DATE(2026,7,15)+TIME(10,0,0),'Raw Data'!L2:L1001,"<"&DATE(2026,7,15)+TIME(11,0,0)) -> 42 | C13: =C12+B13 -> 184
A14: 11:00 | B14: =COUNTIFS('Raw Data'!E2:E1001,TRUE(),'Raw Data'!L2:L1001,">="&DATE(2026,7,15)+TIME(11,0,0),'Raw Data'!L2:L1001,"<"&DATE(2026,7,15)+TIME(12,0,0)) -> 54 | C14: =C13+B14 -> 238
A15: 12:00 | B15: =COUNTIFS('Raw Data'!E2:E1001,TRUE(),'Raw Data'!L2:L1001,">="&DATE(2026,7,15)+TIME(12,0,0),'Raw Data'!L2:L1001,"<"&DATE(2026,7,15)+TIME(13,0,0)) -> 44 | C15: =C14+B15 -> 282
A16: 13:00 | B16: =COUNTIFS('Raw Data'!E2:E1001,TRUE(),'Raw Data'!L2:L1001,">="&DATE(2026,7,15)+TIME(13,0,0),'Raw Data'!L2:L1001,"<"&DATE(2026,7,15)+TIME(14,0,0)) -> 40 | C16: =C15+B16 -> 322
A17: 14:00 | B17: =COUNTIFS('Raw Data'!E2:E1001,TRUE(),'Raw Data'!L2:L1001,">="&DATE(2026,7,15)+TIME(14,0,0),'Raw Data'!L2:L1001,"<"&DATE(2026,7,15)+TIME(15,0,0)) -> 45 | C17: =C16+B17 -> 367
A18: 15:00 | B18: =COUNTIFS('Raw Data'!E2:E1001,TRUE(),'Raw Data'!L2:L1001,">="&DATE(2026,7,15)+TIME(15,0,0),'Raw Data'!L2:L1001,"<"&DATE(2026,7,15)+TIME(16,0,0)) -> 34 | C18: =C17+B18 -> 401
A19: 16:00 | B19: =COUNTIFS('Raw Data'!E2:E1001,TRUE(),'Raw Data'!L2:L1001,">="&DATE(2026,7,15)+TIME(16,0,0),'Raw Data'!L2:L1001,"<"&DATE(2026,7,15)+TIME(17,0,0)) -> 43 | C19: =C18+B19 -> 444
A20: 17:00 | B20: =COUNTIFS('Raw Data'!E2:E1001,TRUE(),'Raw Data'!L2:L1001,">="&DATE(2026,7,15)+TIME(17,0,0),'Raw Data'!L2:L1001,"<"&DATE(2026,7,15)+TIME(18,0,0)) -> 47 | C20: =C19+B20 -> 491
A21: 18:00 | B21: =COUNTIFS('Raw Data'!E2:E1001,TRUE(),'Raw Data'!L2:L1001,">="&DATE(2026,7,15)+TIME(18,0,0),'Raw Data'!L2:L1001,"<"&DATE(2026,7,15)+TIME(19,0,0)) -> 0 | C21: =C20+B21 -> 491
A23: VOTER STATUS SUMMARY
A24: Status | B24: Count | C24: Percentage
A25: Approved | B25: =COUNTIF('Raw Data'!F2:F1001,"APPROVED") -> 303 | C25: =IF(SUM(B$25:B$27)=0,0,B25/SUM(B$25:B$27)) -> 0.303
A26: Pending | B26: =COUNTIF('Raw Data'!F2:F1001,"PENDING") -> 369 | C26: =IF(SUM(B$25:B$27)=0,0,B26/SUM(B$25:B$27)) -> 0.369
A27: Rejected | B27: =COUNTIF('Raw Data'!F2:F1001,"REJECTED") -> 328 | C27: =IF(SUM(B$25:B$27)=0,0,B27/SUM(B$25:B$27)) -> 0.328
